<mujoco>
	<option gravity="0 0 -9.81" />
	<worldbody>
        <light diffuse=".5 .5 .5" pos="0 0 3" dir="0 0 -1"/>
		<geom type="plane" size="5 5 0.1" rgba=".9 .9 .9 1"/>
		<body name = "chassis" pos="0 0 0.5" euler='0 30 0'>
        <joint type="free"/>
			<geom type="box" size=".04 .2 .5" rgba="0 0 0 1" mass="3"/>
            <body pos="0 0 1" euler="0 5 0">
            <joint name="pin" type="hinge" axis="0 -1 0" pos="0 0 -0.5"/>
                <geom type="box" size=".04 .2 .6" rgba="0 0 0.5 1" mass="3"/>
                <body name="front-right-tire" pos="0 -0.3 0.5" euler='90 0 0'>
                    <joint name = "front-right-wheel" type="hinge" axis="0 0 -1"/>
                    <geom type="cylinder" size=".2 0.05" rgba="0 .9 0 1"/>
                </body>
                <body name="front-left-tire" pos="0 0.3 0.5" euler='90 0 0'>
                    <joint name = "front-left-wheel" type="hinge" axis="0 0 -1"/>
                    <geom type="cylinder" size=".2 0.05" rgba="0 .9 0 1"/>
                </body>
            </body>
			<body name="left-tire" pos="0 0.3 -0.5" euler='90 0 0'>
				<joint name = "left-wheel" type="hinge" axis="0 0 -1"/>
				<geom type="cylinder" size=".2 0.05" rgba="0 .9 0 1"/>
			</body>
			<body name="right-tire" pos="0 -0.3 -0.5" euler='90 0 0'>
				<joint name = "right-wheel" type="hinge" axis="0 0 -1"/>
				<geom type="cylinder" size=".2 0.05" rgba="0 .9 0 1"/>
			</body>

		</body>
	</worldbody>
	<actuator>
        <velocity name="left-v" joint="left-wheel" kv="100"/>
        <velocity name="right-v" joint="right-wheel" kv="100"/>
        <velocity name="left-f-v" joint="front-left-wheel" kv="100"/>
        <velocity name="right-f-v" joint="front-right-wheel" kv="100"/>
    </actuator>
</mujoco>